[2024-06-25T22:42:43.993+0000] {local_task_job_runner.py:120} INFO - ::group::Pre task execution logs
[2024-06-25T22:42:44.017+0000] {taskinstance.py:2076} INFO - Dependencies all met for dep_context=non-requeueable deps ti=<TaskInstance: sp_budget_pipeline.app-sp_budget manual__2024-06-25T22:42:15.133087+00:00 [queued]>
[2024-06-25T22:42:44.025+0000] {taskinstance.py:2076} INFO - Dependencies all met for dep_context=requeueable deps ti=<TaskInstance: sp_budget_pipeline.app-sp_budget manual__2024-06-25T22:42:15.133087+00:00 [queued]>
[2024-06-25T22:42:44.025+0000] {taskinstance.py:2306} INFO - Starting attempt 1 of 2
[2024-06-25T22:42:44.065+0000] {taskinstance.py:2330} INFO - Executing <Task(DockerOperator): app-sp_budget> on 2024-06-25 22:42:15.133087+00:00
[2024-06-25T22:42:44.082+0000] {warnings.py:112} WARNING - /home/***/.local/lib/python3.12/site-packages/***/task/task_runner/standard_task_runner.py:61: DeprecationWarning: This process (pid=81) is multi-threaded, use of fork() may lead to deadlocks in the child.
  pid = os.fork()

[2024-06-25T22:42:44.086+0000] {standard_task_runner.py:63} INFO - Started process 82 to run task
[2024-06-25T22:42:44.087+0000] {standard_task_runner.py:90} INFO - Running: ['***', 'tasks', 'run', 'sp_budget_pipeline', 'app-sp_budget', 'manual__2024-06-25T22:42:15.133087+00:00', '--job-id', '19', '--raw', '--subdir', 'DAGS_FOLDER/sp_budget_pipeline.py', '--cfg-path', '/tmp/tmpsyh5l0ya']
[2024-06-25T22:42:44.090+0000] {standard_task_runner.py:91} INFO - Job 19: Subtask app-sp_budget
[2024-06-25T22:42:44.172+0000] {task_command.py:426} INFO - Running <TaskInstance: sp_budget_pipeline.app-sp_budget manual__2024-06-25T22:42:15.133087+00:00 [running]> on host 257b93314acf
[2024-06-25T22:42:44.387+0000] {taskinstance.py:2648} INFO - Exporting env vars: AIRFLOW_CTX_DAG_EMAIL='***@***.com' AIRFLOW_CTX_DAG_OWNER='engenharia-dados' AIRFLOW_CTX_DAG_ID='sp_budget_pipeline' AIRFLOW_CTX_TASK_ID='app-sp_budget' AIRFLOW_CTX_EXECUTION_DATE='2024-06-25T22:42:15.133087+00:00' AIRFLOW_CTX_TRY_NUMBER='1' AIRFLOW_CTX_DAG_RUN_ID='manual__2024-06-25T22:42:15.133087+00:00'
[2024-06-25T22:42:44.390+0000] {taskinstance.py:430} INFO - ::endgroup::
[2024-06-25T22:42:44.436+0000] {docker.py:366} INFO - Starting docker container from image etl-engine:latest
[2024-06-25T22:42:44.439+0000] {docker.py:374} WARNING - Using remote engine or docker-in-docker and mounting temporary volume from host is not supported. Falling back to `mount_tmp_dir=False` mode. You can set `mount_tmp_dir` parameter to False to disable mounting and remove the warning
[2024-06-25T22:42:44.441+0000] {taskinstance.py:441} INFO - ::group::Post task execution logs
[2024-06-25T22:42:44.441+0000] {taskinstance.py:2905} ERROR - Task failed with exception
Traceback (most recent call last):
  File "/home/airflow/.local/lib/python3.12/site-packages/docker/api/client.py", line 275, in _raise_for_status
    response.raise_for_status()
  File "/home/airflow/.local/lib/python3.12/site-packages/requests/models.py", line 1021, in raise_for_status
    raise HTTPError(http_error_msg, response=self)
requests.exceptions.HTTPError: 400 Client Error: Bad Request for url: http+docker://localhost/v1.45/containers/create?name=etl-engine___app-sp_budget

The above exception was the direct cause of the following exception:

Traceback (most recent call last):
  File "/home/airflow/.local/lib/python3.12/site-packages/airflow/providers/docker/operators/docker.py", line 371, in _run_image
    return self._run_image_with_mounts([*self.mounts, tmp_mount], add_tmp_variable=True)
           ^^^^^^^^^^^^^^^^^^^^^^^^^^^^^^^^^^^^^^^^^^^^^^^^^^^^^^^^^^^^^^^^^^^^^^^^^^^^^
  File "/home/airflow/.local/lib/python3.12/site-packages/airflow/providers/docker/operators/docker.py", line 398, in _run_image_with_mounts
    self.container = self.cli.create_container(
                     ^^^^^^^^^^^^^^^^^^^^^^^^^^
  File "/home/airflow/.local/lib/python3.12/site-packages/docker/api/container.py", line 440, in create_container
    return self.create_container_from_config(config, name, platform)
           ^^^^^^^^^^^^^^^^^^^^^^^^^^^^^^^^^^^^^^^^^^^^^^^^^^^^^^^^^
  File "/home/airflow/.local/lib/python3.12/site-packages/docker/api/container.py", line 457, in create_container_from_config
    return self._result(res, True)
           ^^^^^^^^^^^^^^^^^^^^^^^
  File "/home/airflow/.local/lib/python3.12/site-packages/docker/api/client.py", line 281, in _result
    self._raise_for_status(response)
  File "/home/airflow/.local/lib/python3.12/site-packages/docker/api/client.py", line 277, in _raise_for_status
    raise create_api_error_from_http_exception(e) from e
          ^^^^^^^^^^^^^^^^^^^^^^^^^^^^^^^^^^^^^^^
  File "/home/airflow/.local/lib/python3.12/site-packages/docker/errors.py", line 39, in create_api_error_from_http_exception
    raise cls(e, response=response, explanation=explanation) from e
docker.errors.APIError: 400 Client Error for http+docker://localhost/v1.45/containers/create?name=etl-engine___app-sp_budget: Bad Request ("invalid mount config for type "bind": bind source path does not exist: /tmp/airflowtmpubqhikme")

During handling of the above exception, another exception occurred:

Traceback (most recent call last):
  File "/home/airflow/.local/lib/python3.12/site-packages/docker/api/client.py", line 275, in _raise_for_status
    response.raise_for_status()
  File "/home/airflow/.local/lib/python3.12/site-packages/requests/models.py", line 1021, in raise_for_status
    raise HTTPError(http_error_msg, response=self)
requests.exceptions.HTTPError: 409 Client Error: Conflict for url: http+docker://localhost/v1.45/containers/create?name=etl-engine___app-sp_budget

The above exception was the direct cause of the following exception:

Traceback (most recent call last):
  File "/home/airflow/.local/lib/python3.12/site-packages/airflow/models/taskinstance.py", line 465, in _execute_task
    result = _execute_callable(context=context, **execute_callable_kwargs)
             ^^^^^^^^^^^^^^^^^^^^^^^^^^^^^^^^^^^^^^^^^^^^^^^^^^^^^^^^^^^^^
  File "/home/airflow/.local/lib/python3.12/site-packages/airflow/models/taskinstance.py", line 432, in _execute_callable
    return execute_callable(context=context, **execute_callable_kwargs)
           ^^^^^^^^^^^^^^^^^^^^^^^^^^^^^^^^^^^^^^^^^^^^^^^^^^^^^^^^^^^^
  File "/home/airflow/.local/lib/python3.12/site-packages/airflow/models/baseoperator.py", line 401, in wrapper
    return func(self, *args, **kwargs)
           ^^^^^^^^^^^^^^^^^^^^^^^^^^^
  File "/home/airflow/.local/lib/python3.12/site-packages/airflow/providers/docker/operators/docker.py", line 509, in execute
    return self._run_image()
           ^^^^^^^^^^^^^^^^^
  File "/home/airflow/.local/lib/python3.12/site-packages/airflow/providers/docker/operators/docker.py", line 380, in _run_image
    return self._run_image_with_mounts(self.mounts, add_tmp_variable=False)
           ^^^^^^^^^^^^^^^^^^^^^^^^^^^^^^^^^^^^^^^^^^^^^^^^^^^^^^^^^^^^^^^^
  File "/home/airflow/.local/lib/python3.12/site-packages/airflow/providers/docker/operators/docker.py", line 398, in _run_image_with_mounts
    self.container = self.cli.create_container(
                     ^^^^^^^^^^^^^^^^^^^^^^^^^^
  File "/home/airflow/.local/lib/python3.12/site-packages/docker/api/container.py", line 440, in create_container
    return self.create_container_from_config(config, name, platform)
           ^^^^^^^^^^^^^^^^^^^^^^^^^^^^^^^^^^^^^^^^^^^^^^^^^^^^^^^^^
  File "/home/airflow/.local/lib/python3.12/site-packages/docker/api/container.py", line 457, in create_container_from_config
    return self._result(res, True)
           ^^^^^^^^^^^^^^^^^^^^^^^
  File "/home/airflow/.local/lib/python3.12/site-packages/docker/api/client.py", line 281, in _result
    self._raise_for_status(response)
  File "/home/airflow/.local/lib/python3.12/site-packages/docker/api/client.py", line 277, in _raise_for_status
    raise create_api_error_from_http_exception(e) from e
          ^^^^^^^^^^^^^^^^^^^^^^^^^^^^^^^^^^^^^^^
  File "/home/airflow/.local/lib/python3.12/site-packages/docker/errors.py", line 39, in create_api_error_from_http_exception
    raise cls(e, response=response, explanation=explanation) from e
docker.errors.APIError: 409 Client Error for http+docker://localhost/v1.45/containers/create?name=etl-engine___app-sp_budget: Conflict ("Conflict. The container name "/etl-engine___app-sp_budget" is already in use by container "e4a2fc210a36a05df3a7b79bfce20d0104d4decefb8634fb10bd7c13b29921ef". You have to remove (or rename) that container to be able to reuse that name.")
[2024-06-25T22:42:44.452+0000] {taskinstance.py:1206} INFO - Marking task as UP_FOR_RETRY. dag_id=sp_budget_pipeline, task_id=app-sp_budget, run_id=manual__2024-06-25T22:42:15.133087+00:00, execution_date=20240625T224215, start_date=20240625T224244, end_date=20240625T224244
[2024-06-25T22:42:44.491+0000] {standard_task_runner.py:110} ERROR - Failed to execute job 19 for task app-sp_budget (409 Client Error for http+docker://localhost/v1.45/containers/create?name=etl-engine___app-sp_budget: Conflict ("Conflict. The container name "/etl-engine___app-sp_budget" is already in use by container "e4a2fc210a36a05df3a7b79bfce20d0104d4decefb8634fb10bd7c13b29921ef". You have to remove (or rename) that container to be able to reuse that name."); 82)
[2024-06-25T22:42:44.503+0000] {local_task_job_runner.py:240} INFO - Task exited with return code 1
[2024-06-25T22:42:44.525+0000] {taskinstance.py:3503} INFO - 0 downstream tasks scheduled from follow-on schedule check
[2024-06-25T22:42:44.549+0000] {local_task_job_runner.py:222} INFO - ::endgroup::
